Workbook

Sheet Read Me
A1: UNCS — Rebate Program (Multi-Config) — Test Case Workbook
A2: Prepared following the standard Software Testing Life Cycle (STLC)
A4: Purpose | B4: This workbook takes the "Rebate Program — Final Requirements" document and the six annotated UI captures supplied by the requester (Platform project > sample feature using AI > "3. Rebate program - can setup multiple program") and turns them into an executable STLC test case suite, in the team's standard column and section-banner format.
A7: Tab guide
A8: Test Plan Summary | B8: Scope, environment, roles, entry/exit criteria, and a live execution dashboard.
A9: Assumptions & Open Qs | B9: 14 items that could not be confirmed from the partially-accessible source doc — resolve these before treating results as final.
A10: RTM | B10: Maps each requirement to the test cases that cover it.
A11: Test Cases | B11: 127 test cases, ordered Real-time Rebate first, then Daily Rebate, then shared/cross-cutting concerns (Access Control, Localization, Regression). Generic mechanics that apply to both types (Modify, Delete, Group Targeting, the rate table, and several List/Create checks) are mirrored once per type so each block reads as a complete, standalone suite — e.g. "A1. Real-time Rebate Program List" then, later, "B1. Daily Rebate Program List". Each row: Test Scenario / Test Case / Pre-Condition / Test Steps / Test Data / Expected Results / Post Condition / Actual Result / Status(Pass/Fail) / Important Level / Version / Last Update / Case Type.
A13: Source-access note
A14: Only a short preview of the linked Google Doc could be retrieved — the Objective sentence, cut off partway through — since the full body requires sign-in and isn't reachable via the Google Drive connection linked to this workspace. The Figma connector was also unavailable (the connected account's View seat had hit its MCP tool-call limit on the Professional plan). This suite was built from the Objective sentence plus six manually-captured UI screenshots the requester attached directly. Anything not confirmable from those sources is logged in "Assumptions & Open Qs" rather than guessed at.
A19: How to execute
A20: 1. | B20: Test cases are grouped under numbered section banners (e.g. "1. PRIZE POOL SETUP") matching the module structure — scroll or use the AutoFilter on the header row.
A21: 2. | B21: Fill in Actual Result with what actually happened; Post Condition is there to confirm the resulting system state matched expectations too.
A22: 3. | B22: Set Status via the dropdown: Pass or Fail. Leave it blank until the case has actually been run.
A23: 4. | B23: Version starts at v1.0 for this whole suite; bump it if you revise a case after a spec change. Last Update is stamped to the date each case was authored/last revised.
A24: 5. | B24: The Test Plan Summary tab's dashboard totals update automatically as Status is filled in.
A25: 6. | B25: Prioritize the Settlement Processing and Game-Category Rebate Rate Table sections early — they're the most financially sensitive and have the most open Assumptions riding on them.
A27: Legend
A28: Important Level
A29: High
A30: Medium
A31: Low

Sheet Test Plan Summary
A1: Test Plan Summary
A2: Rebate Program (Multi-Config) — Real-time & Daily Programs, Agent/User Group Targeting
A4: Feature | B4: Rebate Program — multi-configuration enhancement: independent Real-time and Daily rebate programs, each assignable to Agent and User Groups, with type-scoped uniqueness and automated settlement.
A6: Objective (per doc) | B6: Enhance the rebate feature to support multiple Real-time and Daily rebate programs, assign each program to Agents and User Groups, prevent overlapping assignments within the same rebate type, and guarantee correct settlement processing.
A8: Source documents | B8: "Rebate Program — Final Requirements" / 返水计划 — 最终需求 (Google Doc, partial access — see Assumptions tab) and six annotated UI captures supplied by the requester.
A10: Module location | B10: UNCS merchant admin back-office, Rebate Management > Rebate programs (Real-time rebate / Daily rebate tabs).
A12: Roles required | B12: Super Admin and Admin test accounts with access to Rebate Management; Agent and ordinary-user accounts for negative access-control checks.
A14: In scope | B14: Rebate program list for both types and its Modify/Delete actions; type-level global settings (Min Claim/Release/Expire Time/Status); Create and Modify for Real-time and Daily programs; Agent/User Group targeting and type-scoped duplicate-pairing validation; the auto-populated game-category rebate-rate table; Real-time vs. Daily settlement processing; role-based access; English/Chinese localization; regression against the prior single-program rebate behavior.
A16: Out of scope (assumed) | B16: The member-facing claim UI itself, if a manual claim step exists beyond automatic settlement; the underlying turnover/loss calculation engine internals; Agent/User Group creation (covered by their own modules).
A18: Entry criteria | B18: Feature deployed to the test environment; at least two Agent groups and two User Groups pre-configured; test accounts able to generate qualifying game activity for settlement testing.
A20: Exit criteria | B20: All High-priority test cases executed and passed, particularly around settlement accuracy; every item in "Assumptions & Open Qs" resolved or explicitly accepted; no open High-severity defects.
A22: Test types covered | B22: Functional, Negative, Boundary, Integration, Access Control, Localization, Regression.
A25: Execution Dashboard (updates automatically from the Test Cases tab)
A26: Metric | B26: Count
A27: Total test cases | B27: =COUNTIF('Test Cases'!A3:A152,"RBMP-*") -> 121
A28: Passed | B28: =COUNTIF('Test Cases'!J3:J152,"Pass") -> 9
A29: Failed | B29: =COUNTIF('Test Cases'!J3:J152,"Fail") -> 0
A30: Not run | B30: =COUNTIF('Test Cases'!A3:A152,"RBMP-*")-COUNTIF('Test Cases'!J3:J152,"Pass")-COUNTIF('Test Cases'!J3:J152,"Fail") -> 112
A31: High-priority cases | B31: =COUNTIF('Test Cases'!K3:K152,"High") -> 50

Sheet Assumptions & Open Qs
A1: Assumptions & Open Questions
A2: Log these against the full requirement doc before/while executing — several affect settlement accuracy
A4: ID | B4: Area | C4: Assumption / Open Question | D4: Why it matters | E4: Related Test Cases
A5: AQ-01 | B5: Global vs. per-program Status | C5: Does toggling the type-level Global Status to Inactive override/suspend every program of that type regardless of its own Status, or is it purely informational? | D5: Changes the expected result of the global-status test case and downstream settlement behavior. | E5: RBMP-010
A6: AQ-02 | B6: Min Claim semantics | C6: Does a calculated rebate below the Real-time Min Claim threshold get withheld, rolled over to the next period, or forfeited entirely? | D6: Determines the expected result of the sub-threshold settlement test case. | E6: RBMP-052, RBMP-008
A7: AQ-03 | B7: Daily Release/Expire Time boundary | C7: Is the exact Expire Time instant still inside the claim window (inclusive) or already past it (exclusive)? | D7: Determines the expected result of the boundary-timing test cases. | E7: RBMP-108, RBMP-063
A8: AQ-04 | B8: Program Name uniqueness scope | C8: Must Program Name be unique overall, unique per rebate type, or not enforced at all? | D8: Changes the expected result of the duplicate-name test case. | E8: RBMP-020 (Real-time), RBMP-075 (Daily)
A9: AQ-05 | B9: Deleting an Active program | C9: Is deleting a currently Active rebate program allowed outright, gated behind an extra warning given in-flight settlement, or blocked until deactivated first? | D9: Materially changes the expected result — this has real settlement/payout implications. | E9: RBMP-031 (Real-time), RBMP-086 (Daily)
A10: AQ-06 | B10: Maximum rebate rate & decimal precision | C10: Is there a documented ceiling per game category (e.g. cannot exceed 100%), and how many decimal places are supported and stored? | D10: Needed for exact pass/fail thresholds on the rebate-rate boundary tests. | E10: RBMP-048/RBMP-103 (max rate), RBMP-049/RBMP-104 (decimal precision)
A11: AQ-07 | B11: Structure behind "all 56 games" | C11: Does 56 refer to individual game titles auto-mapped under the visible categories, or 56 category rows? The captures show roughly 6-7 category rows (Live Casino, Slot, Sportsbook, Fishing, eSports, Lottery). | D11: Needed to confirm the expected table contents precisely. | E11: RBMP-043 (Real-time), RBMP-098 (Daily)
A12: AQ-08 | B12: Sub-threshold / cross-period rollover | C12: When a calculated rebate falls below Min Claim (Real-time) or right at a Daily cutover, does any amount roll into the next period, or reset to zero? | D12: Affects settlement-accuracy expectations broadly. | E12: RBMP-052, RBMP-108
A13: AQ-09 | B13: Per-tab filter/search persistence | C13: Does the search/status filter reset when switching between the Real-time and Daily tabs, or is it remembered independently per tab? | D13: Changes the expected result of the tab-switch UI test case. | E13: RBMP-112
A14: AQ-10 | B14: Role permission matrix | C14: Does the Admin role have the same rights as Super Admin for Rebate program management, or a restricted subset (e.g. no Delete)? | D14: Affects the precise expected result of every Access-control test case. | E14: RBMP-116
A15: AQ-11 | B15: "Default" User Group semantics | C15: What does selecting "Default" as a User Group actually target (e.g. users not otherwise grouped)? | D15: Affects the expected result and duplicate-check correctness for that selection. | E15: RBMP-042 (Real-time), RBMP-097 (Daily)
... A18: AQ-14 | B18: Full bilingual copy | C18: Only the error banner and screen titles were visible in Chinese in the captures; the doc's remaining sections likely hold the final approved copy for every label and message. | D18: Needed to build copy-exact localization test data instead of a structural check only. | E18: RBMP-121, RBMP-122

Sheet RTM
A1: Requirement Traceability Matrix
A2: Requirements are grouped Real-time first, then Daily, then shared/cross-cutting — matching the Test Cases tab
A4: Req ID | B4: Requirement | C4: Source | D4: Covered By | E4: Coverage
A5: REQ-A1 | B5: Real-time rebate program list — view, search/filter, Modify/Delete, pagination (Real-time tab). | C5: UI Note 1 (program list) | D5: RBMP-001 … RBMP-006 | E5: Covered — pending AQ-09
A6: REQ-A2 | B6: Real-time global rebate settings — Min Claim, Expire Time, Status. | C6: UI Note 1 (global settings panel) | D6: RBMP-007 … RBMP-010 | E6: Covered — pending AQ-01
A7: REQ-A3 | B7: Create a Real-time rebate program — name, status, targeting, game rebate rates. | C7: UI Note 2 | D7: RBMP-011 … RBMP-021 | E7: Covered — pending AQ-04
A8: REQ-A4 | B8: Modify an existing Real-time rebate program. | C8: Inferred from the list's "Modify" action | D8: RBMP-022 … RBMP-029 | E8: Covered
A9: REQ-A5 | B9: Delete a Real-time rebate program. | C9: Inferred from the list's "Delete" action | D9: RBMP-030 … RBMP-033 | E9: Covered — pending AQ-05
A10: REQ-A6 | B10: Agent/User Group targeting for Real-time programs. | C10: UI Note 3 (transfer selection) | D10: RBMP-034 … RBMP-042 | E10: Covered — pending AQ-11
A11: REQ-A7 | B11: Game-category rebate rate table for Real-time programs. | C11: UI Note 2 | D11: RBMP-043 … RBMP-050 | E11: Covered — pending AQ-06, AQ-07, AQ-13
A12: REQ-A8 | B12: Real-time settlement processing. | C12: Doc §1 Objective | D12: RBMP-051 … RBMP-055 | E12: Covered — pending AQ-02, AQ-08
A13: REQ-B1 | B13: Daily rebate program list — view, search/filter, Modify/Delete, pagination (Daily tab). | C13: UI Note 4 (program list) | D13: RBMP-056 … RBMP-061 | E13: Covered — pending AQ-09
A14: REQ-B2 | B14: Daily global rebate settings — Release Time, Expire Time, Status. | C14: UI Note 4 (global settings panel) | D14: RBMP-062 … RBMP-064 | E14: Covered
A15: REQ-B3 | B15: Create a Daily rebate program — name, status, targeting, game rebate rates. | C15: UI Note 5 | D15: RBMP-065 … RBMP-076 | E15: Covered — pending AQ-04
... A24: REQ-C4 | B24: Multi-program enhancement must not break existing single-program rebate data or behavior. | C24: Doc §1 Objective | D24: RBMP-124 … RBMP-127 | E24: Covered — pending AQ-12

Sheet Test Cases
A1: Project Name | B1: Admin Weibo | D1: =(COUNTIF(J11:J399,E1))/F1 -> 0.20512821 | E1: Pass | F1: =COUNTIF(G11:G399,"<>") -> 156 | G1: Test cases
A2: Module Name | B2: Rebate management | D2: =COUNTIF(J9:J59,E2)/F1 -> 0 | E2: Fail | F2: =ROWS(A:A) -> 1000 | G2: ROW'S COUNT | I2: Re 100, Bet A 60, A 50
A3: Version | B3: V. 3. 16. 0 | D3: =COUNTIF(J9:J59,E3)/F1 -> 0 | E3: Pending | I3: A earlier, 40 remaing, then B, 50 - 40 = 10,
A4: Created By | B4: Am Rithysak / Sengmean | D4: =SUM(D1:D3) -> 0.20512821 | E4: TOTAL
A5: Date of Creation | B5: 45957
A6: Date of Review | B6: =IFERROR(__xludf.DUMMYFUNCTION("TO_DATE(MAX(N:N))"),0.0) -> 0
A8: HKD
A9: Rebate Program (Multi-Config) — Test Cases
A10: TEST CASE ID | B10: TEST SCENARIO | C10: TEST CASE | D10: PRE-CONDITION | E10: TEST STEPS | F10: TEST DATA | G10: EXPECTED RESULTS | H10: POST CONDITION | I10: ACTUAL RESULT | J10: STATUS(PASS/FAIL) | K10: Important Level | L10: VERSION | M10: LAST UPDATE | N10: CASE TYPE
A11: — REAL-TIME REBATE
A12: A1. Real-time Rebate Program List
A13: RBMP-001 | B13: Verify Program List functionality for listing only Real-time programs with correct summary data on that tab | C13: Real-time tab lists only Real-time programs with correct summary data | D13: Logged in to the Weibo Empire admin back-office as Super Admin/Admin with access to Rebate Management > Rebate programs. On the Rebate program setup screen. Real-time rebate tab selected. At least 2 Real-time programs exist. | E13: 1. Navigate to Rebate Management > Rebate programs. 2. Confirm the Real-time tab is active. 3. Review the program table. | F13: 2 sample Real-time programs, e.g. "Sample 1", "Sample 2". | G13: The table shows Program name, Target Agents, User Groups, Status and Last update for each Real-time program only; no Daily programs appear on this tab. | H13: No system state change; the list continues to reflect existing Real-time program data. | K13: High | L13: v2.0 | M13: 46280 | N13: Functional
A14: RBMP-002 | B14: Verify Real-time Program List functionality for searching/filtering the list by name or target | C14: Search/filter the program list by name or target | D14: Logged in to the Weibo Empire admin back-office as Super Admin/Admin with access to Rebate Management > Rebate programs. On the Rebate program setup screen. Real-time rebate tab selected. | E14: 1. Enter a known program name (or Agent/User Group name) into the search box. 2. Apply the search. | F14: Search text matching "Sample 1". | G14: Only the matching program(s) are shown; clearing the search restores the full list. | H14: No system state change; only the displayed filtered results change. | K14: Medium | L14: v2.0 | M14: 46280 | N14: Functional
A15: RBMP-003 | B15: Verify Real-time Program List functionality for filtering by Status — All, Active, or Inactive | C15: Filter by Status (All / Active / Inactive) | D15: Logged in to the Weibo Empire admin back-office as Super Admin/Admin with access to Rebate Management > Rebate programs. On the Rebate program setup screen. Real-time rebate tab selected. A mix of Active and Inactive programs exist. | E15: 1. Set the status filter to Active. 2. Set it to Inactive. 3. Set it back to All. | F15: Mixed-status program set. | G15: Each filter shows only programs matching that status; All shows every program regardless of status. | H15: No system state change; only the displayed filtered results change. | K15: Medium | L15: v2.0 | M15: 46280 | N15: Functional
A16: RBMP-004 | B16: Verify Real-time Program List functionality for opening the correct program pre-filled from Modify | C16: Modify action opens the correct program pre-filled | D16: Logged in to the Weibo Empire admin back-office as Super Admin/Admin with access to Rebate Management > Rebate programs. On the Rebate program setup screen. Real-time rebate tab selected. | E16: 1. Click Modify on a specific program row. 2. Compare every field to that program's last-saved configuration. | F16: Any existing program with non-default groups and rates. | G16: Program Name, Status, Agent groups, User Groups and the game rebate-rate table are all display exactly as last saved. | H16: No system state change; the Modify screen simply displays the program's already-saved configuration. | K16: High | L16: v2.0 | M16: 46280 | N16: Functional
A17: RBMP-005 | B17: Verify Real-time Program List functionality for requiring confirmation before Delete removes a program | C17: Delete requires confirmation and removes the program | D17: Logged in to the Weibo Empire admin back-office as Super Admin/Admin with access to Rebate Management > Rebate programs. On the Rebate program setup screen. Real-time rebate tab selected. | E17: 1. Click Delete on a program row. 2. Observe the confirmation prompt. 3. Click Cancel, then repeat and Confirm. | F17: Any existing test program. | G17: 1. Cancelling leaves the program untouched; 2. Confirming removes it from the list. | H17: The program is removed from the system if confirmed, or remains untouched if cancelled. | K17: High | L17: v2.0 | M17: 46280 | N17: Functional
A18: RBMP-006 | B18: Verify Real-time Program List functionality for paginating the list | C18: Pagination on the program list | D18: Logged in to the Weibo Empire admin back-office as Super Admin/Admin with access to Rebate Management > Rebate programs. On the Rebate program setup screen. Real-time rebate tab selected. More programs exist than fit on one page. | E18: 1. Create enough programs to exceed one page. 2. Use Previous/Next to page through the list. | F18: More than one page's worth of programs on one tab. | G18: "Showing X-Y of Z rebate programs" and page controls stay accurate on every page, independently per tab. | H18: No system state change; only the displayed page changes. | K18: Low | L18: v2.0 | M18: 46280 | N18: UI
A19: A2. Real-time Global Rebate Settings
A20: RBMP-007 | B20: Verify Global Settings functionality for displaying the current saved Real-time values | C20: Real-time global settings display current saved values | D20: Logged in to the Weibo Empire admin back-office as Super Admin/Admin with access to Rebate Management > Rebate programs. On the Rebate program setup screen. Real-time rebate tab selected. | E20: 1. View the Global real-time rebate settings panel. | F20: Previously saved Min Claim / Expire Time / Status. | G20: Min Claim, Expire Time and Status all reflect the last-saved values. | H20: No system state change; displayed values match what was last saved. | K20: Medium | L20: v2.0 | M20: 46280 | N20: Functional
A21: RBMP-008 | B21: Verify Global Settings functionality for saving valid changes to the Real-time settings | C21: Save valid changes to Real-time global settings | D21: Logged in to the Weibo Empire admin back-office as Super Admin/Admin with access to Rebate Management > Rebate programs. On the Rebate program setup screen. Real-time rebate tab selected. | E21: 1. Change Min Claim and/or Expire Time to valid values. 2. Click Save. | F21: Min Claim = 10; Expire Time = 24 (hours). - <<valid account>> - - - 7 - [from TC_REBATE_008] - <<valid account>> - - - 24 - [from TC_REBATE_010] | G21: Values persist after a page reload; a Save confirmation is shown. - Should be successfully modified - On the client, the release time of rebate amount should change according to the admin config - Should be successfully modified - Rebate amount should expired according to the config of expiration time NOTE: Expiration time will count after settled rebate | H21: The Real-time global settings are updated and apply to all Real-time programs going forward. | J21: Pass | K21: High | L21: V. 3.11.0 | M21: 3/23/2026 | N21: Functional
A22: RBMP-009 | B22: Verify Global Settings functionality for rejecting negative or non-numeric input in Real-time Min Claim | C22: Real-time Min Claim rejects negative or non-numeric input | D22: Logged in to the Weibo Empire admin back-office as Super Admin/Admin with access to Rebate Management > Rebate programs. On the Rebate program setup screen. Real-time rebate tab selected. | E22: 1. Enter a negative number into Min Claim. 2. Enter non-numeric text into Min Claim. 3. Click Save. | F22: -5, "abc". - <<valid account>> - - - -7 - [from TC_REBATE_009] | G22: Save is blocked with a validation message for both invalid inputs. Should not allow negative amount | H22: The Real-time global settings remain at their last validly saved values. | J22: Pass | K22: High | L22: V. 3.11.0 | M22: 3/23/2026 | N22: Negative
A23: RBMP-010 | B23: Verify Global Settings functionality for the effect of toggling Real-time global Status to Inactive on all Real-time programs | C23: Toggling Real-time global Status to Inactive affects all Real-time programs | D23: Logged in to the Weibo Empire admin back-office as Super Admin/Admin with access to Rebate Management > Rebate programs. On the Rebate program setup screen. Real-time rebate tab selected. At least one Active Real-time program exists. | E23: 1. Set the global Status to Inactive. 2. Save. 3. Check whether the individually-Active Real-time program still functions/settles. | F23: Global Status = Inactive. - <<valid account>> - - - Disabled - [from TC_REBATE_011] | G23: Confirm against AQ-01 whether the global toggle is a master switch overriding per-program Status, or purely informational. After disabled, should stop calculating the settle rebate amount process | H23: System behavior for all Real-time programs matches the confirmed global-override rule (see AQ-01). | J23: Pass | K23: High | L23: V. 3.11.0 | M23: 3/23/2026 | N23: Integration
A24: A3. Create Real-time Rebate Program
A25: RBMP-011 | B25: Verify Create Program functionality for creating a Real-time program with all fields valid | C25: Create a Real-time rebate program with all fields valid | D25: Logged in to the Weibo Empire admin back-office as Super Admin/Admin with access to Rebate Management > Rebate programs. On the Create Real-time rebate program screen. | E25: 1. Enter a unique Program Name. 2. Select Agent group(s) and User Group(s) whose pairing isn't used by another Real-time program. 3. Set a rebate rate on at least one game category. 4. Click Submit. | F25: Name = "New Real-time Rebate"; LIVE CASINO rate = 0.3%. | G25: The program is created and appears on the Real-time tab with the entered data; Status defaults to Inactive unless changed. | H25: A new Real-time rebate program exists, holding its Agent/User Group pairing(s) against future same-type duplicates. | K25: High | L25: v2.0 | M25: 46280 | N25: Functional
A26: RBMP-012 | B26: Verify Real-time Create Program functionality for fixing the rebate Type so it cannot be changed on the Create screen | C26: A program's rebate Type is fixed and cannot be changed on the Create screen | D26: Logged in to the Weibo Empire admin back-office as Super Admin/Admin with access to Rebate Management > Rebate programs. On the Create Real-time rebate program screen. | E26: 1. Open Create from the Real-time tab and look for any control to change the program's type. 2. Repeat by opening Create from the Daily tab. | F26: N/A. | G26: No control exists to change type; a Real-time program can only be created from the Real-time tab's Create action, and likewise for Daily. | H26: No system state change; only the absence of a type-change control is verified. | K26: Medium | L26: v2.0 | M26: 46280 | N26: Functional
A27: RBMP-013 | B27: Verify Real-time Create Program functionality for attempting to create a program with an empty Program Name | C27: Attempt to create a program with an empty Program Name | D27: Logged in to the Weibo Empire admin back-office as Super Admin/Admin with access to Rebate Management > Rebate programs. On the Create Real-time rebate program screen. | E27: 1. Leave Program Name blank. 2. Complete the rest validly. 3. Click Submit. | F27: Name = "". | G27: Submit is blocked with a required-field message; no program is added. | H27: No new program is created; the program list is unchanged. | K27: High | L27: v2.0 | M27: 46280 | N27: Negative
A28: RBMP-014 | B28: Verify Real-time Create Program functionality for attempting to create a program with no Agent group or no User Group selected | C28: Attempt to create a program with no Agent group or no User Group selected | D28: Logged in to the Weibo Empire admin back-office as Super Admin/Admin with access to Rebate Management > Rebate programs. On the Create Real-time rebate program screen. | E28: 1. Leave the Agent group Selected column empty (or the User Group Selected column empty). 2. Click Submit. | F28: 0 Agent groups selected. | G28: Submit is blocked; the documented rule states every program must contain at least one Target Agent and one User Group. | H28: Require atlease one of pair group for one program | K28: High | L28: v2.0 | M28: 46280 | N28: Negative
A29: RBMP-015 | B29: Verify Real-time Create Program functionality for blocking creation when the pairing duplicates another program of the same type | C29: Create is blocked when the pairing duplicates another program of the SAME type | D29: Logged in to the Weibo Empire admin back-office as Super Admin/Admin with access to Rebate Management > Rebate programs. On the Create Real-time rebate program screen. Another Active Real-time program already uses the target pairing. | E29: 1. Select Agent/User Group matching an existing Real-time program's pairing. 2. Click Submit. | F29: Pairing already used by an existing Real-time program. | G29: Submit is blocked with "Target Agent and User Group duplicate to other program"; no partial program is created. | H29: No new program is created; the pre-existing conflicting program's pairing is untouched. | K29: High | L29: v2.0 | M29: 46280 | N29: Negative
A30: RBMP-016 | B30: Verify Real-time Create Program functionality for succeeding on resubmission after correcting a flagged duplicate-pairing conflict | C30: Resubmitting after correcting a flagged duplicate-pairing conflict succeeds | D30: Continuing directly from a blocked Real-time submission due to a duplicate-pairing conflict. | E30: 1. Change only the conflicting group selection. 2. Click Submit again. | F30: Deselect the conflicting User Group only. | G30: Program Name and entered rates are preserved; Submit now succeeds. | H30: A new program now exists with the corrected pairing; the previously conflicting program is unaffected. | K30: Medium | L30: v2.0 | M30: 46280 | N30: Functional
A31: RBMP-017 | B31: Verify Real-time Create Program functionality for defaulting a new program to Inactive regardless of entered data | C31: New program defaults to Inactive regardless of entered data | D31: Logged in to the Weibo Empire admin back-office as Super Admin/Admin with access to Rebate Management > Rebate programs. On the Create Real-time rebate program screen. | E31: 1. Complete the form without touching Status. 2. Submit. | F31: Status left untouched. | G31: The created program shows Status = Inactive in the list, consistent with the documented default. | H31: The new program exists with Status = Inactive until explicitly activated. | K31: Medium | L31: v2.0 | M31: 46280 | N31: Functional
A32: RBMP-018 | B32: Verify Real-time Create Program functionality for honoring an explicitly-set Active status on create | C32: Explicitly setting Status = Active on create is honored | D32: Logged in to the Weibo Empire admin back-office as Super Admin/Admin with access to Rebate Management > Rebate programs. On the Create Real-time rebate program screen. | E32: 1. Change Status to Active before submitting. 2. Submit. | F32: Status = Active. | G32: The created program shows Status = Active in the list. | H32: The new program exists with Status = Active. | K32: Medium | L32: v2.0 | M32: 46280 | N32: Functional
A33: RBMP-019 | B33: Verify Real-time Create Program functionality for discarding a partially-completed form on Cancel | C33: Cancel discards a partially-completed Create form | D33: Logged in to the Weibo Empire admin back-office as Super Admin/Admin with access to Rebate Management > Rebate programs. On the Create Real-time rebate program screen. | E33: 1. Fill in several fields. 2. Click Cancel. | F33: Any partial entry. | G33: No program is created; the Program list is unchanged. | H33: No new program is created; the program list is unchanged. | K33: Medium | L33: v2.0 | M33: 46280 | N33: Functional
A34: RBMP-020 | B34: Verify Real-time Create Program functionality for handling a Program Name identical to an existing program | C34: Create a program using a Program Name identical to an existing program | D34: Logged in to the Weibo Empire admin back-office as Super Admin/Admin with access to Rebate Management > Rebate programs. On the Create Real-time rebate program screen. Another program already uses the name being entered. | E34: 1. Enter a Program Name that exactly matches an existing program (same or other type). 2. Complete the rest validly. 3. Click Submit. | F34: Name = an existing program's exact name. | G34: System block, and show an error message | H34: System state the name as uniqueness rule | K34: Low | L34: v2.0 | M34: 46280 | N34: Negative
A35: RBMP-021 | B35: Verify Real-time Create Program functionality for handling boundary input in the Program Name field, including very long text and special characters | C35: Program Name field boundary — very long text and special characters | D35: Logged in to the Weibo Empire admin back-office as Super Admin/Admin with access to Rebate Management > Rebate programs. On the Create Real-time rebate program screen. | E35: 1. Enter a name at/above the expected character limit, including special characters/emoji. 2. Submit. | F35: 200 character string with symbols and emoji. | G35: The field enforces a sensible maximum length and does not break the program list layout. | H35: Either a program with a safely-truncated name exists, or none was created if the input was rejected outright. | K35: Low | L35: v2.0 | M35: 46280 | N35: Boundary
A36: A4. Modify Real-time Rebate Program
A37: RBMP-022 | B37: Verify Real-time Modify Program functionality for saving a change to Program Name | C37: Modify and save a change to Program Name | D37: Logged in to the Weibo Empire admin back-office as Super Admin/Admin with access to Rebate Management > Rebate programs. Modifying an existing Real-time rebate program. | E37: 1. Open Modify on an existing program. 2. Change the name. 3. Click Update. | F37: New unique name. | G37: The list reflects the new name. | H37: The program's name is updated everywhere it is referenced. | K37: Medium | L37: v2.0 | M37: 46280 | N37: Functional
A38: RBMP-023 | B38: Verify Real-time Modify Program functionality for toggling a program's Status between Active and Inactive | C38: Toggle a program's Status between Active and Inactive | D38: Logged in to the Weibo Empire admin back-office as Super Admin/Admin with access to Rebate Management > Rebate programs. Modifying an existing Real-time rebate program. | E38: 1. Change Status. 2. Click Update. | F38: Toggle Active <-> Inactive. | G38: The list reflects the new Status immediately. | H38: The program's Status matches the newly saved value. | K38: High | L38: v2.0 | M38: 46280 | N38: Functional
A39: RBMP-024 | B39: Verify Real-time Modify Program functionality for blocking a pairing change to one already used by another program of the same type | C39: Modify the pairing to one already used by another program of the same type | D39: Logged in to the Weibo Empire admin back-office as Super Admin/Admin with access to Rebate Management > Rebate programs. Modifying an existing Real-time rebate program. Another program of the same type already owns the target pairing. | E39: 1. Change the group selection to duplicate another same-type program's pairing. 2. Click Update. | F39: Target pairing already in use. | G39: Update is blocked with the duplicate-pairing error; unrelated field edits are preserved for correction. | H39: The program's pairing remains at its last saved value; the conflicting program elsewhere is unaffected. | K39: High | L39: v2.0 | M39: 46280 | N39: Negative
A40: RBMP-025 | B40: Verify Real-time Modify Program functionality for saving unrelated field changes while leaving the program's own pairing unchanged | C40: Modify unrelated fields while leaving the program's own pairing unchanged | D40: Logged in to the Weibo Empire admin back-office as Super Admin/Admin with access to Rebate Management > Rebate programs. Modifying an existing Real-time rebate program. | E40: 1. Change only a game category's rebate rate. 2. Leave the groups unchanged. 3. Click Update. | F40: Change one rate value. | G40: Update succeeds; the program's own unchanged pairing is not flagged as a conflict against itself. | H40: The program's rebate rate is updated; its Agent/User Group pairing remains exactly as before. | K40: Medium | L40: v2.0 | M40: 46280 | N40: Functional
A41: RBMP-026 | B41: Verify Real-time Modify Program functionality for changing a game category's rebate rate | C41: Change a game category's rebate rate | D41: Logged in to the Weibo Empire admin back-office as Super Admin/Admin with access to Rebate Management > Rebate programs. Modifying an existing Real-time rebate program. | E41: 1. Change one category's rate, e.g. SLOT from 1.2% to 1.5%. 2. Click Update. | F41: SLOT 1.2% -> 1.5%. - <<valid account>> - - - - 4% - [from TC_REBATE_014] | G41: The new rate saves and is reflected for future settlement calculations. - Should be successfully modified -The rebate amount of games should be calculated with the percentage that was set for each game | H41: The program's game-category rate reflects the new value for future settlement calculations. | J41: Pass | K41: Medium | L41: V. 3.11.0 | M41: 3/23/2026 | N41: Functional
...

Sheet Other Category
A1: Other Category — Test Cases
A2: TEST CASE ID | B2: TEST SCENARIO | C2: TEST CASE | D2: PRE-CONDITION | E2: TEST STEPS | F2: TEST DATA | G2: EXPECTED RESULTS | H2: POST CONDITION | I2: ACTUAL RESULT | J2: STATUS(PASS/FAIL) | K2: Important Level | L2: VERSION | M2: LAST UPDATE | N2: CASE TYPE
A3: 1. CATEGORY LIST
A4: OC-LST-001 | B4: Verify Category List functionality for displaying all categories with correct summary data | C4: Category list shows icon, name, games count, status, and order for every category | D4: Logged in to the Weibo Empire admin back-office as Super Admin/Admin with access to Product > Other Category. On the Other Category list screen. At least 2 categories exist. | E4: 1. Navigate to Product > Other Category. 2. Review the category list. | F4: Existing categories, e.g. "Popular Games", "Live Casino". | G4: Each row shows the correct Icon, Category name, Games count, Status, and Order matching that category's saved configuration. | H4: No system state change; the list continues to reflect existing category data. | K4: High | L4: v1.0 | M4: 46288 | N4: Functional
A5: OC-LST-002 | B5: Verify Category List functionality for searching the list by category name | C5: Search returns only categories matching the entered text | D5: Logged in to the Weibo Empire admin back-office as Super Admin/Admin with access to Product > Other Category. On the Other Category list screen. | E5: 1. Enter a known category name into the search box. 2. Apply the search. | F5: Search text matching "Popular". | G5: Only categories whose name matches are shown; clearing the search restores the full list. | H5: No system state change; only the displayed filtered results change. | K5: Medium | L5: v1.0 | M5: 46288 | N5: Functional
A6: OC-LST-003 | B6: Verify Category List functionality for filtering by Status | C6: Status filter shows only Active or only Inactive categories as selected | D6: Logged in to the Weibo Empire admin back-office as Super Admin/Admin with access to Product > Other Category. On the Other Category list screen. A mix of Active and Inactive categories exist. | E6: 1. Set the status filter to Active. 2. Set it to Inactive. 3. Set it back to All statuses. | F6: Mixed-status category set. | G6: Each filter shows only categories matching that status; All statuses shows every category. | H6: No system state change; only the displayed filtered results change. | K6: Medium | L6: v1.0 | M6: 46288 | N6: Functional
A7: OC-LST-004 | B7: Verify Category List functionality for previewing category names in a selected language | C7: Changing the list's language filter updates the Category name column to that language's translation | D7: Logged in to the Weibo Empire admin back-office as Super Admin/Admin with access to Product > Other Category. On the Other Category list screen. | E7: 1. Note the Category name shown for a category under the current language filter. 2. Change the language filter to a different supported language. 3. Re-check the same category's displayed name. | F7: Switch from 繁體 to English. | G7: The Category name column updates to show that category's name in the newly selected language, without changing any other column. | H7: No system state change; only the displayed language changes. | K7: Medium | L7: v1.0 | M7: 46288 | N7: Localization
A8: OC-LST-005 | B8: Verify Category List functionality for changing the number of rows shown per page | C8: Page-size selector controls how many categories are listed at once | D8: Logged in to the Weibo Empire admin back-office as Super Admin/Admin with access to Product > Other Category. On the Other Category list screen. More categories exist than the smallest available page size. | E8: 1. Change the per-page selector from 50 to a smaller value. 2. Observe the row count and pagination. | F8: Per-page = 10 (or smallest available option). | G8: The list shows no more than the selected number of rows; pagination updates to match. | H8: No system state change; only the displayed page size changes. | K8: Low | L8: v1.0 | M8: 46288 | N8: UI
A9: OC-LST-006 | B9: Verify Category List functionality for paginating the list | C9: Previous/Next controls navigate between pages of categories | D9: Logged in to the Weibo Empire admin back-office as Super Admin/Admin with access to Product > Other Category. On the Other Category list screen. More categories exist than fit on one page. | E9: 1. Click Next. 2. Click Previous. | F9: More than one page's worth of categories. | G9: "Showing X-Y of Z categories" and the page controls stay accurate on every page. | H9: No system state change; only the displayed page changes. | K9: Low | L9: v1.0 | M9: 46288 | N9: UI
A10: OC-LST-007 | B10: Verify Category List functionality for keeping the Games count accurate | C10: The Games column matches the actual number of games assigned via Manage Games | D10: Logged in to the Weibo Empire admin back-office as Super Admin/Admin with access to Product > Other Category. On the Other Category list screen. | E10: 1. Note a category's Games count. 2. Open Manage Games for that category and add one game. 3. Save and return to the list. | F10: Add 1 game to a category currently showing "8 games". | G10: The Games count updates to "9 games", matching the actual saved assignment count. | H10: The category's Games count reflects its current assignment total. | K10: High | L10: v1.0 | M10: 46288 | N10: Integration
A11: OC-LST-008 | B11: Verify Category List functionality for sorting categories by Display Order | C11: Categories are listed in ascending Display Order | D11: Logged in to the Weibo Empire admin back-office as Super Admin/Admin with access to Product > Other Category. On the Other Category list screen. At least 3 categories with distinct Order values exist. | E11: 1. Review the sequence of categories in the list. 2. Compare against each category's saved Order value. | F11: Categories with Order 01, 02, 03. | G11: Categories appear in ascending Order (lowest number first), consistent with the documented "lower numbers appear first" rule (see AQ-05 for tie-breaking when two categories share a value). | H11: No system state change; only the display sequence is verified. | K11: Medium | L11: v1.0 | M11: 46288 | N11: Functional
A12: 2. CREATE OTHER CATEGORY
A13: OC-CRT-001 | B13: Verify Create Category functionality for creating a category with all 12 language names, an icon, and a valid order | C13: Create succeeds with a complete, valid category | D13: Logged in to the Weibo Empire admin back-office as Super Admin/Admin with access to Product > Other Category. On the Create Other Category screen. | E13: 1. Enter a name for each of the 12 language tabs. 2. Upload a valid category icon. 3. Set Status = Active and Display order = 05. 4. Click Save & manage games. | F13: 繁體 name = "熱門遊戲"; English name = "Popular Games"; icon = valid PNG; order = 05. | G13: The category is created and the admin is taken to its Manage Games screen; the new category later appears in the list with the correct icon, status, and order. | H13: A new Other Category exists in the system, with all entered language names saved. | K13: High | L13: v1.0 | M13: 46288 | N13: Functional
A14: OC-CRT-002 | B14: Verify Create Category functionality for attempting to save with one or more language names left blank | C14: Creating a category while a language tab's name is empty | D14: Logged in to the Weibo Empire admin back-office as Super Admin/Admin with access to Product > Other Category. On the Create Other Category screen. | E14: 1. Fill in names for 11 of the 12 language tabs, leaving one blank. 2. Attempt to save. | F14: Bengali tab left empty. | G14: Confirm against AQ-01 whether all 12 names are mandatory; if so, save is blocked with a message naming the incomplete language(s). | H14: No new category is created unless a blank language name is confirmed acceptable (see AQ-01). | K14: High | L14: v1.0 | M14: 46288 | N14: Negative
A15: OC-CRT-003 | B15: Verify Create Category functionality for editing only the active language tab's name field | C15: The Category Name input shows and edits only the currently selected language tab | D15: Logged in to the Weibo Empire admin back-office as Super Admin/Admin with access to Product > Other Category. On the Create Other Category screen. | E15: 1. Select the English tab and note the input field's label and content. 2. Select the 日語 tab and compare. | F15: English vs. 日語 tabs. | G15: The field label and content change to match whichever tab is active; no other language's name is visible or editable at the same time. | H15: No system state change; only the active-tab display is verified. | K15: Medium | L15: v1.0 | M15: 46288 | N15: UI
A16: OC-CRT-004 | B16: Verify Create Category functionality for preserving already-entered names when switching language tabs | C16: Entering a name on one tab and switching away does not lose it | D16: Logged in to the Weibo Empire admin back-office as Super Admin/Admin with access to Product > Other Category. On the Create Other Category screen. | E16: 1. Enter a name on the English tab. 2. Switch to the Spain tab and enter a different name. 3. Switch back to English. | F16: English = "Popular Games"; Spain = "Juegos populares". | G16: The English tab still shows "Popular Games" after switching away and back; neither tab's value overwrote the other. | H16: Both language names remain held in the unsaved form state until Save is clicked. | K16: High | L16: v1.0 | M16: 46288 | N16: Functional
A17: OC-CRT-005 | B17: Verify Create Category functionality for accepting a PNG category icon | C17: Uploading a PNG file for the category icon | D17: Logged in to the Weibo Empire admin back-office as Super Admin/Admin with access to Product > Other Category. On the Create Other Category screen. | E17: 1. Click Upload category icon. 2. Select a valid .png file. | F17: A valid PNG image. | G17: The PNG uploads successfully and is shown as the selected icon. | H17: The category's icon is set to the uploaded PNG, pending Save. | K17: Medium | L17: v1.0 | M17: 46288 | N17: Functional
A18: OC-CRT-006 | B18: Verify Create Category functionality for accepting JPG and SVG category icons | C18: Uploading a JPG file, then an SVG file, for the category icon | D18: Logged in to the Weibo Empire admin back-office as Super Admin/Admin with access to Product > Other Category. On the Create Other Category screen. | E18: 1. Upload a valid .jpg file as the icon. 2. Replace it with a valid .svg file. | F18: A valid JPG, then a valid SVG. | G18: Both formats upload successfully, consistent with the documented "PNG, JPG or SVG" rule for category icons. | H18: The category's icon is set to the most recently uploaded file, pending Save. | K18: Medium | L18: v1.0 | M18: 46288 | N18: Functional
A19: OC-CRT-007 | B19: Verify Create Category functionality for rejecting an unsupported category icon file type | C19: Attempting to upload a GIF or PDF as the category icon | D19: Logged in to the Weibo Empire admin back-office as Super Admin/Admin with access to Product > Other Category. On the Create Other Category screen. | E19: 1. Click Upload category icon. 2. Attempt to select a .gif or .pdf file. | F19: An unsupported file type, e.g. .gif. | G19: The upload is rejected with a message naming the accepted formats (PNG, JPG, SVG). | H19: No icon is set from the rejected file; any previously uploaded icon is unchanged. | K19: High | L19: v1.0 | M19: 46288 | N19: Negative
A20: OC-CRT-008 | B20: Verify Create Category functionality for attempting to save without uploading an icon | C20: Creating a category with no icon selected | D20: Logged in to the Weibo Empire admin back-office as Super Admin/Admin with access to Product > Other Category. On the Create Other Category screen. | E20: 1. Fill in all 12 language names. 2. Leave Upload category icon empty. 3. Attempt to save. | F20: No icon file selected. | G20: Confirm whether an icon is mandatory; if so, save is blocked with a required-field message. | H20: No new category is created unless a missing icon is confirmed acceptable. | K20: Medium | L20: v1.0 | M20: 46288 | N20: Negative
A21: OC-CRT-009 | B21: Verify Create Category functionality for rejecting non-numeric input in Display order | C21: Entering letters or symbols into the Display order field | D21: Logged in to the Weibo Empire admin back-office as Super Admin/Admin with access to Product > Other Category. On the Create Other Category screen. | E21: 1. Enter non-numeric text into Display order, e.g. "abc". 2. Attempt to save. | F21: Display order = "abc". | G21: The field rejects non-numeric input, or save is blocked with a validation message. | H21: No new category is created; the order field remains at its prior or default value. | K21: Medium | L21: v1.0 | M21: 46288 | N21: Negative
A22: OC-CRT-010 | B22: Verify Create Category functionality for handling a Display order value already used by another category | C22: Creating a category with the same Order as an existing one | D22: Logged in to the Weibo Empire admin back-office as Super Admin/Admin with access to Product > Other Category. On the Create Other Category screen. Another category already uses Order = 01. | E22: 1. Set Display order = 01, matching an existing category. 2. Complete the rest validly and save. | F22: Order = 01 (duplicate). | G22: Confirm against AQ-05 whether duplicate Order values are allowed, auto-renumbered, or blocked, and how the list breaks the tie. | H22: System state matches whichever duplicate-order rule is confirmed. | K22: Medium | L22: v1.0 | M22: 46288 | N22: Boundary
A23: OC-CRT-011 | B23: Verify Create Category functionality for navigating to Manage Games immediately after saving | C23: Clicking Save & manage games opens Manage Games for the newly created category | D23: Logged in to the Weibo Empire admin back-office as Super Admin/Admin with access to Product > Other Category. On the Create Other Category screen. | E23: 1. Complete the form validly. 2. Click Save & manage games. | F23: A newly completed category form. | G23: The category is saved and the admin lands on the Manage Games screen scoped to this new category, with its name shown in the breadcrumb. | H23: The new category exists with zero games assigned until games are selected on the next screen. | K23: High | L23: v1.0 | M23: 46288 | N23: Functional
A24: OC-CRT-012 | B24: Verify Create Category functionality for discarding a partially-completed form on Cancel | C24: Clicking Cancel during Create does not save anything | D24: Logged in to the Weibo Empire admin back-office as Super Admin/Admin with access to Product > Other Category. On the Create Other Category screen. | E24: 1. Fill in several fields. 2. Click Cancel. | F24: Any partial entry. | G24: No new category is created; the category list is unchanged. | H24: No new category is created; the category list is unchanged. | K24: Medium | L24: v1.0 | M24: 46288 | N24: Functional
A25: 3. EDIT OTHER CATEGORY
A26: OC-EDT-001 | B26: Verify Edit Category functionality for opening an existing category pre-filled | C26: Edit loads every saved field correctly, including all 12 language names | D26: Logged in to the Weibo Empire admin back-office as Super Admin/Admin with access to Product > Other Category. On the Other Category list screen. An existing category with names in multiple languages is selected for Edit. | E26: 1. Click Edit on an existing category. 2. Check each of the 12 language tabs, plus icon, status, and order. | F26: An existing category, e.g. "Live Casino". | G26: Every field is pre-populated exactly as last saved, including the correct name under each language tab. | H26: No system state change; the Edit screen simply displays the category's already-saved configuration. | K26: High | L26: v1.0 | M26: 46288 | N26: Functional
A27: OC-EDT-002 | B27: Verify Edit Category functionality for editing a single language's name without affecting the others | C27: Changing only the English name leaves the other 11 languages untouched | D27: Logged in to the Weibo Empire admin back-office as Super Admin/Admin with access to Product > Other Category. Editing an existing Other Category. | E27: 1. Switch to the English tab and change the name. 2. Save. 3. Reopen Edit and check the other language tabs. | F27: Change English name only. | G27: Only the English name reflects the change; all other language names remain exactly as they were. | H27: The category's English name is updated; all other language names are unchanged. | K27: High | L27: v1.0 | M27: 46288 | N27: Functional
A28: OC-EDT-003 | B28: Verify Edit Category functionality for replacing the category icon | C28: Uploading a new icon during Edit replaces the previous one | D28: Logged in to the Weibo Empire admin back-office as Super Admin/Admin with access to Product > Other Category. Editing an existing Other Category. | E28: 1. Upload a new icon file. 2. Save. | F28: A new valid icon file. | G28: The category's icon updates to the new file everywhere it's displayed, including the list. | H28: The category's icon is replaced; the previous icon file is no longer referenced. | K28: Medium | L28: v1.0 | M28: 46288 | N28: Functional
A29: OC-EDT-004 | B29: Verify Edit Category functionality for toggling Status between Active and Inactive | C29: Changing Status and saving updates the category's visibility state | D29: Logged in to the Weibo Empire admin back-office as Super Admin/Admin with access to Product > Other Category. Editing an existing Other Category. | E29: 1. Change Status to Inactive. 2. Save. | F29: Toggle Active -> Inactive. | G29: The list reflects the new Status immediately; the category stops appearing on the client UI (see Client-Facing Display section). | H29: The category's Status is updated to the newly saved value. | K29: High | L29: v1.0 | M29: 46288 | N29: Functional
A30: OC-EDT-005 | B30: Verify Edit Category functionality for re-sorting the list after a Display order change | C30: Lowering a category's Order moves it earlier in the list | D30: Logged in to the Weibo Empire admin back-office as Super Admin/Admin with access to Product > Other Category. Editing an existing Other Category. | E30: 1. Change Display order to a lower number than currently used by other categories. 2. Save and return to the list. | F30: Change Order from 04 to 01. | G30: The category now appears earlier in the list, consistent with the ascending-Order sort rule. | H30: The category's position in the list reflects its new Order value. | K30: Medium | L30: v1.0 | M30: 46288 | N30: Functional
A31: OC-EDT-006 | B31: Verify Edit Category functionality for succeeding on Save when no changes were made | C31: Opening Edit and saving immediately without changes | D31: Logged in to the Weibo Empire admin back-office as Super Admin/Admin with access to Product > Other Category. Editing an existing Other Category. | E31: 1. Open Edit on an existing category. 2. Click Save immediately without changing anything. | F31: No changes. | G31: Save succeeds without error, since nothing was modified. | H31: The category's configuration is unchanged. | K31: Low | L31: v1.0 | M31: 46288 | N31: Functional
A32: OC-EDT-007 | B32: Verify Edit Category functionality for discarding changes on Cancel | C32: Changing fields and clicking Cancel does not save them | D32: Logged in to the Weibo Empire admin back-office as Super Admin/Admin with access to Product > Other Category. Editing an existing Other Category. | E32: 1. Change the icon and one language name. 2. Click Cancel. 3. Reopen Edit. | F32: Any edited value. | G32: The category reflects its last saved state; the cancelled edits are discarded. | H32: The category's configuration is unchanged from before the edit attempt. | K32: Medium | L32: v1.0 | M32: 46288 | N32: Functional
A33: OC-EDT-008 | B33: Verify Edit Category functionality for the primary save action's label and destination | C33: Confirming whether Edit's save button reads "Save" or "Save & manage games", and where it navigates | D33: Logged in to the Weibo Empire admin back-office as Super Admin/Admin with access to Product > Other Category. Editing an existing Other Category. | E33: 1. Note the exact label of the primary button on the Edit screen. 2. Click it and observe where the admin lands. | F33: N/A. | G33: Confirm against AQ-08 whether Edit behaves like Create (navigating into Manage Games) or saves in place and stays on the category list. | H33: System state matches whichever navigation behavior is confirmed for Edit. | K33: Low | L33: v1.0 | M33: 46288 | N33: UI
A34: 4. DELETE OTHER CATEGORY
A35: OC-DEL-001 | B35: Verify Delete Category functionality for showing the correct category name and assignment count in the confirmation | C35: The delete confirmation names the right category and its true game-assignment count | D35: Logged in to the Weibo Empire admin back-office as Super Admin/Admin with access to Product > Other Category. On the Other Category list screen. | E35: 1. Click Delete on a category with a known number of assigned games. 2. Read the confirmation dialog. | F35: A category showing "8 games" in the list. | G35: The dialog names that exact category and states "8 game assignments will be removed", matching the list's Games count. | H35: No system state change; only the confirmation dialog's content is verified. | K35: High | L35: v1.0 | M35: 46288 | N35: Functional
A36: OC-DEL-002 | B36: Verify Delete Category functionality for removing the category once deletion is confirmed | C36: Clicking Delete category in the confirmation removes it from the list | D36: Logged in to the Weibo Empire admin back-office as Super Admin/Admin with access to Product > Other Category. On the Other Category list screen. | E36: 1. Click Delete on a category. 2. Confirm by clicking Delete category. | F36: Any existing test category. | G36: The category no longer appears in the Other Category list. | H36: The category no longer exists in the system. | K36: High | L36: v1.0 | M36: 46288 | N36: Functional
A37: OC-DEL-003 | B37: Verify Delete Category functionality for allowing the delete confirmation to be cancelled | C37: Clicking Cancel in the confirmation dialog does not delete the category | D37: Logged in to the Weibo Empire admin back-office as Super Admin/Admin with access to Product > Other Category. On the Other Category list screen. | E37: 1. Click Delete on a category. 2. Click Cancel in the confirmation dialog. | F37: Any existing test category. | G37: The category remains in the list, fully unchanged. | H37: The category remains in the system, fully unchanged. | K37: Medium | L37: v1.0 | M37: 46288 | N37: Functional
A38: OC-DEL-004 | B38: Verify Delete Category functionality for keeping underlying games available after their category is deleted | C38: A game that was assigned to a deleted category still exists and can be assigned elsewhere | D38: Logged in to the Weibo Empire admin back-office as Super Admin/Admin with access to Product > Other Category. On the Other Category list screen. A category with at least one assigned game is selected for deletion. | E38: 1. Note a game assigned to the category about to be deleted. 2. Delete the category. 3. Open Manage Games for a different category and search for that same game. | F38: A game such as "Horse Racing" assigned to the deleted category. | G38: The game is still findable and selectable, consistent with the documented rule that underlying games and their global records remain available. | H38: The deleted category's game assignments are removed, but the games themselves remain in the system, unaffected. | K38: High | L38: v1.0 | M38: 46288 | N38: Integration
A39: OC-DEL-005 | B39: Verify Delete Category functionality for the fate of per-assignment banners once a category is deleted | C39: Checking whether banners uploaded for the deleted category's game assignments are removed or retained | D39: Logged in to the Weibo Empire admin back-office as Super Admin/Admin with access to Product > Other Category. On the Other Category list screen. A category with at least one game that has an uploaded banner is selected for deletion. | E39: 1. Delete the category. 2. Re-add the same game to a different (or the same, if re-created) category. | F39: A game with a previously uploaded banner, e.g. "Boxing Yes / No". | G39: Confirm against AQ-03 whether the old banner is gone (a fresh upload is required) or was retained and reused for the new assignment. | H39: System state matches whichever banner-retention rule is confirmed. | K39: Medium | L39: v1.0 | M39: 46288 | N39: Integration
A40: OC-DEL-006 | B40: Verify Delete Category functionality for deleting a category that has no games assigned | C40: Deleting a category showing "0 games" in the list | D40: Logged in to the Weibo Empire admin back-office as Super Admin/Admin with access to Product > Other Category. On the Other Category list screen. A category with 0 assigned games exists, e.g. "New Releases". | E40: 1. Click Delete on the zero-game category. 2. Read the confirmation wording. 3. Confirm the deletion. | F40: "New Releases", 0 games. | G40: The confirmation states 0 game assignments will be removed (or omits that line); the category is deleted without error. | H40: The category no longer exists in the system. | K40: Low | L40: v1.0 | M40: 46288 | N40: Boundary
...

Sheet Notification
A1: Notification — Test Cases
A2: TEST CASE ID | B2: TEST SCENARIO | C2: TEST CASE | D2: PRE-CONDITION | E2: TEST STEPS | F2: TEST DATA | G2: EXPECTED RESULTS | H2: POST CONDITION | I2: ACTUAL RESULT | J2: STATUS(PASS/FAIL) | K2: Important Level | L2: VERSION | M2: LAST UPDATE | N2: CASE TYPE
A3: 1. NOTIFICATION LIST
